<?xml version="1.0" encoding="UTF-8"?>
<testng-results retried="3" ignored="0" total="5" passed="1" failed="1" skipped="0">
  <reporter-output>
  </reporter-output>
  <suite started-at="2023-04-14T14:00:47 GMT-04:00" name="Default suite" finished-at="2023-04-14T14:01:36 GMT-04:00" duration-ms="49706">
    <groups>
    </groups>
    <test started-at="2023-04-14T14:00:47 GMT-04:00" name="Default test" finished-at="2023-04-14T14:01:36 GMT-04:00" duration-ms="49706">
      <class name="rerun_failed_testCases.Code">
        <test-method is-config="true" signature="rediffLoginTest()[pri:0, instance:rerun_failed_testCases.Code@75437611]" started-at="2023-04-14T14:00:47 GMT-04:00" name="rediffLoginTest" finished-at="2023-04-14T14:00:52 GMT-04:00" duration-ms="5070" status="PASS">
          <reporter-output>
          </reporter-output>
        </test-method> <!-- rediffLoginTest -->
        <test-method signature="clickOnSigninLink()[pri:1, instance:rerun_failed_testCases.Code@75437611]" started-at="2023-04-14T14:00:52 GMT-04:00" name="clickOnSigninLink" finished-at="2023-04-14T14:00:56 GMT-04:00" duration-ms="4251" status="PASS">
          <reporter-output>
          </reporter-output>
        </test-method> <!-- clickOnSigninLink -->
        <test-method is-config="true" signature="rediffLoginTest()[pri:0, instance:rerun_failed_testCases.Code@75437611]" started-at="2023-04-14T14:00:56 GMT-04:00" name="rediffLoginTest" finished-at="2023-04-14T14:00:59 GMT-04:00" duration-ms="2807" status="PASS">
          <reporter-output>
          </reporter-output>
        </test-method> <!-- rediffLoginTest -->
        <test-method retried="true" signature="enterValidCredentials()[pri:2, instance:rerun_failed_testCases.Code@75437611]" started-at="2023-04-14T14:00:59 GMT-04:00" name="enterValidCredentials" finished-at="2023-04-14T14:01:06 GMT-04:00" duration-ms="7407" status="SKIP">
          <exception class="java.lang.AssertionError">
            <message>
              <![CDATA[just failing it]]>
            </message>
            <full-stacktrace>
              <![CDATA[java.lang.AssertionError: just failing it
at org.testng.Assert.fail(Assert.java:99)
at rerun_failed_testCases.Code.enterValidCredentials(Code.java:33)
at java.base/jdk.internal.reflect.NativeMethodAccessorImpl.invoke0(Native Method)
at java.base/jdk.internal.reflect.NativeMethodAccessorImpl.invoke(NativeMethodAccessorImpl.java:77)
at java.base/jdk.internal.reflect.DelegatingMethodAccessorImpl.invoke(DelegatingMethodAccessorImpl.java:43)
at java.base/java.lang.reflect.Method.invoke(Method.java:568)
at org.testng.internal.MethodInvocationHelper.invokeMethod(MethodInvocationHelper.java:133)
at org.testng.internal.TestInvoker.invokeMethod(TestInvoker.java:598)
at org.testng.internal.TestInvoker.invokeTestMethod(TestInvoker.java:173)
at org.testng.internal.MethodRunner.runInSequence(MethodRunner.java:46)
at org.testng.internal.TestInvoker$MethodInvocationAgent.invoke(TestInvoker.java:824)
at org.testng.internal.TestInvoker.invokeTestMethods(TestInvoker.java:146)
at org.testng.internal.TestMethodWorker.invokeTestMethods(TestMethodWorker.java:146)
at org.testng.internal.TestMethodWorker.run(TestMethodWorker.java:128)
at java.base/java.util.ArrayList.forEach(ArrayList.java:1511)
at org.testng.TestRunner.privateRun(TestRunner.java:794)
at org.testng.TestRunner.run(TestRunner.java:596)
at org.testng.SuiteRunner.runTest(SuiteRunner.java:377)
at org.testng.SuiteRunner.runSequentially(SuiteRunner.java:371)
at org.testng.SuiteRunner.privateRun(SuiteRunner.java:332)
at org.testng.SuiteRunner.run(SuiteRunner.java:276)
at org.testng.SuiteRunnerWorker.runSuite(SuiteRunnerWorker.java:53)
at org.testng.SuiteRunnerWorker.run(SuiteRunnerWorker.java:96)
at org.testng.TestNG.runSuitesSequentially(TestNG.java:1212)
at org.testng.TestNG.runSuitesLocally(TestNG.java:1134)
at org.testng.TestNG.runSuites(TestNG.java:1063)
at org.testng.TestNG.run(TestNG.java:1031)
at org.testng.remote.AbstractRemoteTestNG.run(AbstractRemoteTestNG.java:115)
at org.testng.remote.RemoteTestNG.initAndRun(RemoteTestNG.java:251)
at org.testng.remote.RemoteTestNG.main(RemoteTestNG.java:77)
]]>
            </full-stacktrace>
          </exception> <!-- java.lang.AssertionError -->
          <reporter-output>
          </reporter-output>
        </test-method> <!-- enterValidCredentials -->
        <test-method is-config="true" signature="rediffLoginTest()[pri:0, instance:rerun_failed_testCases.Code@75437611]" started-at="2023-04-14T14:01:06 GMT-04:00" name="rediffLoginTest" finished-at="2023-04-14T14:01:09 GMT-04:00" duration-ms="2962" status="PASS">
          <reporter-output>
          </reporter-output>
        </test-method> <!-- rediffLoginTest -->
        <test-method retried="true" signature="enterValidCredentials()[pri:2, instance:rerun_failed_testCases.Code@75437611]" started-at="2023-04-14T14:01:09 GMT-04:00" name="enterValidCredentials" finished-at="2023-04-14T14:01:15 GMT-04:00" duration-ms="6113" status="SKIP">
          <exception class="java.lang.AssertionError">
            <message>
              <![CDATA[just failing it]]>
            </message>
            <full-stacktrace>
              <![CDATA[java.lang.AssertionError: just failing it
at org.testng.Assert.fail(Assert.java:99)
at rerun_failed_testCases.Code.enterValidCredentials(Code.java:33)
at java.base/jdk.internal.reflect.NativeMethodAccessorImpl.invoke0(Native Method)
at java.base/jdk.internal.reflect.NativeMethodAccessorImpl.invoke(NativeMethodAccessorImpl.java:77)
at java.base/jdk.internal.reflect.DelegatingMethodAccessorImpl.invoke(DelegatingMethodAccessorImpl.java:43)
at java.base/java.lang.reflect.Method.invoke(Method.java:568)
at org.testng.internal.MethodInvocationHelper.invokeMethod(MethodInvocationHelper.java:133)
at org.testng.internal.TestInvoker.invokeMethod(TestInvoker.java:598)
at org.testng.internal.TestInvoker.retryFailed(TestInvoker.java:213)
at org.testng.internal.MethodRunner.runInSequence(MethodRunner.java:58)
at org.testng.internal.TestInvoker$MethodInvocationAgent.invoke(TestInvoker.java:824)
at org.testng.internal.TestInvoker.invokeTestMethods(TestInvoker.java:146)
at org.testng.internal.TestMethodWorker.invokeTestMethods(TestMethodWorker.java:146)
at org.testng.internal.TestMethodWorker.run(TestMethodWorker.java:128)
at java.base/java.util.ArrayList.forEach(ArrayList.java:1511)
at org.testng.TestRunner.privateRun(TestRunner.java:794)
at org.testng.TestRunner.run(TestRunner.java:596)
at org.testng.SuiteRunner.runTest(SuiteRunner.java:377)
at org.testng.SuiteRunner.runSequentially(SuiteRunner.java:371)
at org.testng.SuiteRunner.privateRun(SuiteRunner.java:332)
at org.testng.SuiteRunner.run(SuiteRunner.java:276)
at org.testng.SuiteRunnerWorker.runSuite(SuiteRunnerWorker.java:53)
at org.testng.SuiteRunnerWorker.run(SuiteRunnerWorker.java:96)
at org.testng.TestNG.runSuitesSequentially(TestNG.java:1212)
at org.testng.TestNG.runSuitesLocally(TestNG.java:1134)
at org.testng.TestNG.runSuites(TestNG.java:1063)
at org.testng.TestNG.run(TestNG.java:1031)
at org.testng.remote.AbstractRemoteTestNG.run(AbstractRemoteTestNG.java:115)
at org.testng.remote.RemoteTestNG.initAndRun(RemoteTestNG.java:251)
at org.testng.remote.RemoteTestNG.main(RemoteTestNG.java:77)
]]>
            </full-stacktrace>
          </exception> <!-- java.lang.AssertionError -->
          <reporter-output>
          </reporter-output>
        </test-method> <!-- enterValidCredentials -->
        <test-method is-config="true" signature="rediffLoginTest()[pri:0, instance:rerun_failed_testCases.Code@75437611]" started-at="2023-04-14T14:01:15 GMT-04:00" name="rediffLoginTest" finished-at="2023-04-14T14:01:19 GMT-04:00" duration-ms="3341" status="PASS">
          <reporter-output>
          </reporter-output>
        </test-method> <!-- rediffLoginTest -->
        <test-method retried="true" signature="enterValidCredentials()[pri:2, instance:rerun_failed_testCases.Code@75437611]" started-at="2023-04-14T14:01:19 GMT-04:00" name="enterValidCredentials" finished-at="2023-04-14T14:01:26 GMT-04:00" duration-ms="7201" status="SKIP">
          <exception class="java.lang.AssertionError">
            <message>
              <![CDATA[just failing it]]>
            </message>
            <full-stacktrace>
              <![CDATA[java.lang.AssertionError: just failing it
at org.testng.Assert.fail(Assert.java:99)
at rerun_failed_testCases.Code.enterValidCredentials(Code.java:33)
at java.base/jdk.internal.reflect.NativeMethodAccessorImpl.invoke0(Native Method)
at java.base/jdk.internal.reflect.NativeMethodAccessorImpl.invoke(NativeMethodAccessorImpl.java:77)
at java.base/jdk.internal.reflect.DelegatingMethodAccessorImpl.invoke(DelegatingMethodAccessorImpl.java:43)
at java.base/java.lang.reflect.Method.invoke(Method.java:568)
at org.testng.internal.MethodInvocationHelper.invokeMethod(MethodInvocationHelper.java:133)
at org.testng.internal.TestInvoker.invokeMethod(TestInvoker.java:598)
at org.testng.internal.TestInvoker.retryFailed(TestInvoker.java:213)
at org.testng.internal.MethodRunner.runInSequence(MethodRunner.java:58)
at org.testng.internal.TestInvoker$MethodInvocationAgent.invoke(TestInvoker.java:824)
at org.testng.internal.TestInvoker.invokeTestMethods(TestInvoker.java:146)
at org.testng.internal.TestMethodWorker.invokeTestMethods(TestMethodWorker.java:146)
at org.testng.internal.TestMethodWorker.run(TestMethodWorker.java:128)
at java.base/java.util.ArrayList.forEach(ArrayList.java:1511)
at org.testng.TestRunner.privateRun(TestRunner.java:794)
at org.testng.TestRunner.run(TestRunner.java:596)
at org.testng.SuiteRunner.runTest(SuiteRunner.java:377)
at org.testng.SuiteRunner.runSequentially(SuiteRunner.java:371)
at org.testng.SuiteRunner.privateRun(SuiteRunner.java:332)
at org.testng.SuiteRunner.run(SuiteRunner.java:276)
at org.testng.SuiteRunnerWorker.runSuite(SuiteRunnerWorker.java:53)
at org.testng.SuiteRunnerWorker.run(SuiteRunnerWorker.java:96)
at org.testng.TestNG.runSuitesSequentially(TestNG.java:1212)
at org.testng.TestNG.runSuitesLocally(TestNG.java:1134)
at org.testng.TestNG.runSuites(TestNG.java:1063)
at org.testng.TestNG.run(TestNG.java:1031)
at org.testng.remote.AbstractRemoteTestNG.run(AbstractRemoteTestNG.java:115)
at org.testng.remote.RemoteTestNG.initAndRun(RemoteTestNG.java:251)
at org.testng.remote.RemoteTestNG.main(RemoteTestNG.java:77)
]]>
            </full-stacktrace>
          </exception> <!-- java.lang.AssertionError -->
          <reporter-output>
          </reporter-output>
        </test-method> <!-- enterValidCredentials -->
        <test-method is-config="true" signature="rediffLoginTest()[pri:0, instance:rerun_failed_testCases.Code@75437611]" started-at="2023-04-14T14:01:26 GMT-04:00" name="rediffLoginTest" finished-at="2023-04-14T14:01:29 GMT-04:00" duration-ms="3611" status="PASS">
          <reporter-output>
          </reporter-output>
        </test-method> <!-- rediffLoginTest -->
        <test-method signature="enterValidCredentials()[pri:2, instance:rerun_failed_testCases.Code@75437611]" started-at="2023-04-14T14:01:29 GMT-04:00" name="enterValidCredentials" finished-at="2023-04-14T14:01:36 GMT-04:00" duration-ms="6832" status="FAIL">
          <exception class="java.lang.AssertionError">
            <message>
              <![CDATA[just failing it]]>
            </message>
            <full-stacktrace>
              <![CDATA[java.lang.AssertionError: just failing it
at org.testng.Assert.fail(Assert.java:99)
at rerun_failed_testCases.Code.enterValidCredentials(Code.java:33)
at java.base/jdk.internal.reflect.NativeMethodAccessorImpl.invoke0(Native Method)
at java.base/jdk.internal.reflect.NativeMethodAccessorImpl.invoke(NativeMethodAccessorImpl.java:77)
at java.base/jdk.internal.reflect.DelegatingMethodAccessorImpl.invoke(DelegatingMethodAccessorImpl.java:43)
at java.base/java.lang.reflect.Method.invoke(Method.java:568)
at org.testng.internal.MethodInvocationHelper.invokeMethod(MethodInvocationHelper.java:133)
at org.testng.internal.TestInvoker.invokeMethod(TestInvoker.java:598)
at org.testng.internal.TestInvoker.retryFailed(TestInvoker.java:213)
at org.testng.internal.MethodRunner.runInSequence(MethodRunner.java:58)
at org.testng.internal.TestInvoker$MethodInvocationAgent.invoke(TestInvoker.java:824)
at org.testng.internal.TestInvoker.invokeTestMethods(TestInvoker.java:146)
at org.testng.internal.TestMethodWorker.invokeTestMethods(TestMethodWorker.java:146)
at org.testng.internal.TestMethodWorker.run(TestMethodWorker.java:128)
at java.base/java.util.ArrayList.forEach(ArrayList.java:1511)
at org.testng.TestRunner.privateRun(TestRunner.java:794)
at org.testng.TestRunner.run(TestRunner.java:596)
at org.testng.SuiteRunner.runTest(SuiteRunner.java:377)
at org.testng.SuiteRunner.runSequentially(SuiteRunner.java:371)
at org.testng.SuiteRunner.privateRun(SuiteRunner.java:332)
at org.testng.SuiteRunner.run(SuiteRunner.java:276)
at org.testng.SuiteRunnerWorker.runSuite(SuiteRunnerWorker.java:53)
at org.testng.SuiteRunnerWorker.run(SuiteRunnerWorker.java:96)
at org.testng.TestNG.runSuitesSequentially(TestNG.java:1212)
at org.testng.TestNG.runSuitesLocally(TestNG.java:1134)
at org.testng.TestNG.runSuites(TestNG.java:1063)
at org.testng.TestNG.run(TestNG.java:1031)
at org.testng.remote.AbstractRemoteTestNG.run(AbstractRemoteTestNG.java:115)
at org.testng.remote.RemoteTestNG.initAndRun(RemoteTestNG.java:251)
at org.testng.remote.RemoteTestNG.main(RemoteTestNG.java:77)
]]>
            </full-stacktrace>
          </exception> <!-- java.lang.AssertionError -->
          <reporter-output>
          </reporter-output>
        </test-method> <!-- enterValidCredentials -->
      </class> <!-- rerun_failed_testCases.Code -->
    </test> <!-- Default test -->
  </suite> <!-- Default suite -->
</testng-results>
